Workbook

Sheet Bienvenido
A1: ¡Bienvenido(a)!
A4: La calculadora financiera es una herramienta que tiene el propósito de evaluar tus finanzas personales de una forma simple y rápida.
A6: Además, en ella podrás:
A7: • Concientizar tus hábitos financieros.
A8: • Conocer tu indicador de salud financiera.
A9: • Obtener recomendaciones para mejorar tu salud financiera.
A11: El archivo consiste en capturar tus ingresos y tus gastos según su categoría de forma mensual.
A13: A inicio de mes anota tus ingresos y a partir de ahí, de forma cotidiana, registra tus gastos para que a fin de mes veas cómo distribuiste tus ingresos.
A15: Recuerda ser constante y no olvides ningún gasto o ingreso.
A17: Esperamos que te ayude a descubrir qué tan bueno eres administrando tus finanzas.
A32: Años | B32: Meses
A33: 2022 | B33: Enero
A34: 2023 | B34: Febrero
A35: 2024 | B35: Marzo
A36: 2025 | B36: Abril
A37: 2026 | B37: Mayo
A38: 2027 | B38: Junio
A39: 2028 | B39: Julio
A40: 2029 | B40: Agosto
A41: 2030 | B41: Septiembre
B42: Octubre
B43: Noviembre
B44: Diciembre

Sheet 1) Captura tus ingresos 
A1: Ingresos
A4: Captura aquí tus ingresos según la categoría que corresponda.
A6: Año de captura | B6: 2023
A7: Mes de captura | B7: Enero
A9: Sueldos, vales de despensa, etc. | B9: 0 | D9: Ingreso principal recurrente que recibes cada mes con seguridad.
A11: Becas y otras ayudas económicas | B11: 0 | D11: Becas y otros apoyos económicos que recibas en dinero.
A13: Prestaciones empleado | B13: 0 | D13: Utilidades, prima vacacional, fondo de ahorro, aguinaldo, entre otros.
A15: Ingresos variables | B15: 0 | D15: Comisiones, bonos por lograr ciertas metas, Ingresos por negocios, alquiler o ingresos como trabajador independiente
A17: Finiquito/Liquidación | B17: 0 | D17: Cantidad que recibes al renunciar o ser despedido de una empresa.
A19: Otros ingresos | B19: 0 | D19: Venta de algún bien, préstamos cobrados, inversiones recuperadas, etc.
B20: =SUM(B9:B19) -> 0

Sheet 2) Captura tus gastos
A1: Gastos
A3: Captura aquí tus gastos según la categoría que corresponda.
A4: Los gastos que realices en tu tarjeta de crédito debes capturarlos según su categoría en la fecha en que fueron adquiridos. será más adecuado a tu situación.
A5: De esta forma se reflejará el flujo real por mes y el indicador de salud financiera
A7: Año de captura | B7: ='1) Captura tus ingresos '!B6 -> 2023
A8: Mes de captura | B8: ='1) Captura tus ingresos '!B7 -> Enero
A10: Vivienda | B10: 0 | D10: Monto de la renta o la aportación mensual del crédito, impuestos de la casa, gastos de notario, enganche en caso de compra, depósito en caso de renta, entre otros.
A12: Pago de Servicios | B12: 0 | D12: Recibos de luz, agua, gas, celular e internet.
A14: Despensa | B14: 0 | D14: El famoso "Súper" o compras en el mercado: Alimentos (para preparar), higiene personal, limpieza y hogar.
A16: Comidas preparadas fuera de casa | B16: 0 | D16: Comida preparada fuera de casa, ya sea pedida a domicilio, para llevar o dentro del mismo restaurante.
A18: Salidas | B18: 0 | D18: Salidas a eventos, al cine, con amigos, y otros lugares sociales para entretenimiento o propósitos similares.
A20: Imagen personal | B20: 0 | D20: Dentista, corte de cabello, cremas, mascarillas, maquillaje, tatuajes, y todo lo relacionado a tu apariencia.
A22: Fitness | B22: 0 | D22: Gimnasio, nutrición, suplementos, masajes y otros gastos relacionados con mantener una buena estado físico.
A24: Ropa, calzado y accesorios | B24: 0 | D24: Ropa, calzado, gorras, relojes, cadenas, anillos, etc.
A26: Automóvil | B26: 0 | D26: Mensualidad si lo estás pagando, mantenimiento, impuestos, carwash, placas, renovación licencia, multas, etc.
A28: Transporte | B28: 0 | D28: Gasolina, Uber, Autobus, Metro y/u otros medios de transporte dentro de tu localidad.
A30: Educación | B30: 0 | D30: Colegiaturas, cursos, seminarios, etc.
A32: Seguros | B32: 0 | D32: De Auto, Vida, Gastos Médicos, Hogar, entre otros.
... A54: Otros | B54: 0 | D54: Otros gastos como pago de préstamos bancarios o personales, psicólogo, impuestos, regalos, festejos y cualquier otro no mencionado anteriormente.

Sheet 3) Resultados
B2: =CONCATENATE("Resultados ", '1) Captura tus ingresos '!B7, " ", '1) Captura tus ingresos '!B6) -> Resultados Enero 2023
B5: Tu Indicador de salud financiera: | F5: =IF(N26<=0,IF(N18<=0,"Sin datos",0),ROUND(MAX(0,MIN(100,P33,P38)),1)) -> Sin datos
B7: Este indicador refleja qué tan saludables fueron tus hábitos este mes en una escala del 0 al 100.
B9: =IF(ISNUMBER(F5),IF(P31<0,P43,IF(F5>=85,P41,IF(P32<10%,"Puedes fortalecer tu ahorro e inversión. La calificación combina margen, ahorro y gastos ajustables.",P42))),"Captura tus ingresos y gastos para calcular el indicador.") -> Captura tus ingresos y gastos para calcular el indicador.
B12: Composición de ingresos y gastos
B14: INGRESOS TOTALES: | C14: =N26 -> 0 | G14: GASTOS TOTALES: | K14: =N18 -> 0
N17: Gastos
N18: =SUM(C40:C62) -> 0 | O18: =IF(N18>0,1,0) -> 0 | P18: GASTOS TOTALES
N19: =SUM(C40:C48) -> 0 | O19: =IF(N18>0,N19/N18,0) -> 0 | P19: Gastos indispensables que son complicados de eliminar o reducir
N20: =SUM(C49:C53) -> 0 | O20: =IF(N18>0,N20/N18,0) -> 0 | P20: Gastos importantes y saludables, se recomienda mantenerlos incluso en crisis si es posible
N21: =SUM(C54:C56) -> 0 | O21: =IF(N18>0,N21/N18,0) -> 0 | P21: Gastos que se recomienda pausar o reducir en crisis económicas
N22: =SUM(C57:C61) -> 0 | O22: =IF(N18>0,N22/N18,0) -> 0 | P22: Gastos que se recomienda pausar o reducir en épocas ajustadas
N23: =SUM(C62) -> 0 | O23: =IF(N18>0,N23/N18,0) -> 0 | P23: Gastos que se recomienda pausar o reducir en medida de lo posible sea cual sea tu situación
N25: Ingresos | P25: Leyendas
N26: =SUM('1) Captura tus ingresos '!B9:B19) -> 0 | O26: =IF(N26>0,1,0) -> 0 | P26: INGRESOS TOTALES
N27: ='1) Captura tus ingresos '!B9 -> 0 | O27: =IF(N26>0,N27/N26,0) -> 0 | P27: Ingresos conocidos y estables en el largo plazo
N28: =SUM('1) Captura tus ingresos '!B11:B15) -> 0 | O28: =IF(N26>0,N28/N26,0) -> 0 | P28: Ingresos conocidos o variables, estables en el mediano plazo
N29: =SUM('1) Captura tus ingresos '!B17:B19) -> 0 | O29: =IF(N26>0,N29/N26,0) -> 0 | P29: Ingresos de una ocasión
O31: Saldo después de salidas | P31: =N26-N18 -> 0
O32: Ahorro / ingresos | P32: =IF(N26>0,C53/N26,0) -> 0
O33: Puntos antes del tope | P33: =SUM(P34:P35,P37) -> 0
O34: Margen (hasta 40) | P34: =IF(N26>0,MAX(0,MIN(40,40-20*(N18-C53)/N26)),0) -> 0
O35: Ahorro (hasta 40) | P35: =IF(N26>0,40*MIN(1,MAX(0,P32)/10%),0) -> 0
B37: Desglose de gastos y su categoría | O37: Gastos ajustables (hasta 20) | P37: =IF(N26>0,MAX(0,MIN(20,20*(1-SUM(N21:N23)/N26))),0) -> 0
O38: Tope si hay déficit | P38: =IF(ROUND(P31,2)<0,59,100) -> 100
B39: Concepto | C39: Gasto | D39: Detalle
A40: 1 | B40: Vivienda | C40: ='2) Captura tus gastos'!B10 -> 0 | D40: Gastos indispensables que son complicados de eliminar o reducir | O40: Comportamientos
A41: 1 | B41: Pago de Servicios | C41: ='2) Captura tus gastos'!B12 -> 0 | D41: Gastos indispensables que son complicados de eliminar o reducir | O41: 1 | P41: Este mes has tenido muy buenos resultados, ¡Sigue así!
A42: 1 | B42: Despensa | C42: ='2) Captura tus gastos'!B14 -> 0 | D42: Gastos indispensables que son complicados de eliminar o reducir | O42: 2 | P42: Puedes reducir una parte importante de tus gastos, revisa la sección final e identifica las celdas en color naranja y/o rojo para conocer cuáles
A43: 1 | B43: Automóvil | C43: ='2) Captura tus gastos'!B26 -> 0 | D43: Gastos indispensables que son complicados de eliminar o reducir | O43: 3 | P43: Tus salidas superan tus ingresos. Revisa el presupuesto y los gastos ajustables antes de comprometer más dinero.
A44: 1 | B44: Transporte | C44: ='2) Captura tus gastos'!B28 -> 0 | D44: Gastos indispensables que son complicados de eliminar o reducir
A45: 1 | B45: Educación | C45: ='2) Captura tus gastos'!B30 -> 0 | D45: Gastos indispensables que son complicados de eliminar o reducir
A46: 1 | B46: Salud (recurrentes) | C46: ='2) Captura tus gastos'!B46 -> 0 | D46: Gastos indispensables que son complicados de eliminar o reducir
A47: 1 | B47: Contador e impuestos | C47: ='2) Captura tus gastos'!B48 -> 0 | D47: Gastos indispensables que son complicados de eliminar o reducir
A48: 1 | B48: Gastos imprevistos | C48: ='2) Captura tus gastos'!B50 -> 0 | D48: Gastos indispensables que son complicados de eliminar o reducir
A49: 2 | B49: Fitness | C49: ='2) Captura tus gastos'!B22 -> 0 | D49: Gastos importantes y saludables, se recomienda mantenerlos incluso en crisis si es posible
A50: 2 | B50: Seguros | C50: ='2) Captura tus gastos'!B32 -> 0 | D50: Gastos importantes y saludables, se recomienda mantenerlos incluso en crisis si es posible
A51: 2 | B51: Compra de algún bien duradero | C51: ='2) Captura tus gastos'!B40 -> 0 | D51: Gastos importantes y saludables, se recomienda mantenerlos incluso en crisis si es posible
A52: 2 | B52: Mascotas | C52: ='2) Captura tus gastos'!B44 -> 0 | D52: Gastos importantes y saludables, se recomienda mantenerlos incluso en crisis si es posible
A53: 2 | B53: Ahorro/Inversión | C53: ='2) Captura tus gastos'!B52 -> 0 | D53: Gastos importantes y saludables, se recomienda mantenerlos incluso en crisis si es posible
...
